//In the example below, the type of exception is Exception and the variable name is $e.

<?php
function divide($dividend, $divisor) {
  if($divisor == 0) {
    throw new Exception("Division by zero");
  }
  return $dividend / $divisor;
}

try {
  echo divide(5, 0);
} catch(Exception $e) {
  echo "Unable to divide.";
}
?>



//The try...catch...finally statement can be used to catch exceptions. Code in the finally block will always run regardless of whether an exception was caught. 
//If finally is present, the catch block is optional.

<?php
function divide($dividend, $divisor) {
  if($divisor == 0) {
    throw new Exception("Division by zero");
  }
  return $dividend / $divisor;
}

try {
  echo divide(5, 0);
} catch(Exception $e) {
  echo "Unable to divide. ";
} finally {
  echo "Process complete.";
}
?>

//some of the methods that can be used to get information about the exception:

<?php
function divide($dividend, $divisor) {
  if($divisor == 0) {
    throw new Exception("Division by zero", 1);
  }
  return $dividend / $divisor;
}

try {
  echo divide(5, 0);
} catch(Exception $ex) {
  $code = $ex->getCode();
  $message = $ex->getMessage();
  $file = $ex->getFile();
  $line = $ex->getLine();
  echo "Exception thrown in $file on line $line: [Code $code]
  $message";
}
?>


